Workbook

Sheet Лист1
A1: лист | B1: номер | C1: наименование файла | D1: присланный класс | E1: класс в ответе 1481 | F1: расхождение присланный/ответ | G1: реальный класс документа | H1: расхождение присланный/реальный | I1: ошибка 1481 | J1: Комментарий разработчика | K1: Статус исправления
A2: 5 | B2: NWR-35 | C2: 4080281062******2515_044525104_(01.01.2026_-_14.04.2026).pdf | D2: extended_acc_statement_12_months | E2: ошибка | F2: =D2=E2 -> FALSE | G2: extended_acc_statement_12_months | H2: =D2=G2 -> TRUE | I2: да | J2: Отдельно загруженный документ прошел без ошибок. | K2: исправлено
A3: 5 | B3: NWR-35 | C3: 4080281062******2515_044525104_(01.01.2026_-_14.04.2026).xlsx | D3: extended_acc_statement_12_months | E3: ошибка | F3: =D3=E3 -> FALSE | G3: extended_acc_statement_12_months | H3: =D3=G3 -> TRUE | I3: да | J3: Отдельно загруженный документ упал с ошибкой - "Error prepare pages, input xlsx is invalid". Убрал в эксель пустые строки и столбцы в начале и всё прошло без ошибок. Будет доработка Нади | K3: исправлено
A4: 5 | B4: NWR-35 | C4: Патент_2026_год.pdf | D4: patent | E4: ошибка | F4: =D4=E4 -> FALSE | G4: patent | H4: =D4=G4 -> TRUE | I4: да | J4: Отдельно загруженный документ прошел без ошибок. Распознано атрибутов 2 из 2, но ФЛК работает не правильно. Исправлено добавлением возможности указания будущих дат | K4: исправлено
A5: 5 | B5: NWR-35 | C5: Пояснение.pdf | D5: explanatory_note | E5: ошибка | F5: =D5=E5 -> FALSE | G5: explanatory_note | H5: =D5=G5 -> TRUE | I5: да | J5: Отдельно загруженная прошла без ошибок. Распознано атрибутов 0 из 2, но их там нет | K5: исправлено
A6: 7 | B6: NWR-41 | C6: ce806d64-41fb-46b0-a856-94c81fc9d8d9_(1)-compressed.pdf | D6: tax_declaration | E6: other | F6: =D6=E6 -> FALSE | G6: платежное поручение | H6: =D6=G6 -> FALSE | I6: нет | J6: Не правильно указан тип документа.
A7: 7 | B7: NWR-41 | C7: 0314b9d2-a8e0-469d-a7b1-7296720a7b23(1)-compressed.pdf | D7: extended_acc_statement_12_months | E7: other | F7: =D7=E7 -> FALSE | G7: договор | H7: =D7=G7 -> FALSE | I7: нет | J7: Не правильно указан тип документа.
A8: 7 | B8: NWR-41 | C8: IMG_20260417_153927.jpg | D8: explanatory_note | E8: other | F8: =D8=E8 -> FALSE | G8: пояснительная рукописная | H8: =D8=G8 -> FALSE | I8: нет | J8: Рукописная
A9: 7 | B9: NWR-41 | C9: IMG_20260417_153935.jpg | D9: explanatory_note | E9: other | F9: =D9=E9 -> FALSE | G9: пояснительная рукописная | H9: =D9=G9 -> FALSE | I9: нет | J9: Рукописная
A10: 8 | B10: NWR-34 | C10: IMG_9133.png | D10: 3_ndfl | E10: other | F10: =D10=E10 -> FALSE | G10: скриншот ордера из приложения | H10: =D10=G10 -> FALSE | I10: нет | J10: Не правильно указан тип документа.
A11: 8 | B11: NWR-34 | C11: Документ_27.docx | D11: explanatory_note_crypt | E11: other | F11: =D11=E11 -> FALSE | G11: пояснительная, мало текста | H11: =D11=G11 -> FALSE | I11: нет | J11: Нет ключевых слов, мало текста
A12: 8 | B12: NWR-34 | C12: IMG_9134.png | D12: statement_of_the_transaction_history | E12: other | F12: =D12=E12 -> FALSE | G12: statement_of_the_transaction_history | H12: =D12=G12 -> TRUE | I12: вопрос | J12: Должна классифицироваться???
A13: 9 | B13: NWR-40 | C13: СберБизнес._Выписка_за_2026.01.01-2026.04.17_счёт_40802810850000020909.pdf | D13: extended_acc_statement_12_months | E13: ошибка | F13: =D13=E13 -> FALSE | G13: extended_acc_statement_12_months | H13: =D13=G13 -> TRUE | I13: да | J13: XML ошибка не воспроизвелась. Классификация поправлена | K13: XML ошибка на ифт не воспроизвелась, интеграционно не воспроизвелась
A14: 9 | B14: NWR-40 | C14: IMG_20260417_214826.jpg | D14: patent | E14: ошибка | F14: =D14=E14 -> FALSE | G14: два патента на 1 листе | H14: =D14=G14 -> FALSE | I14: да | J14: XML ошибка не воспроизвелась. Не корректно располагать 2 патента на 1 странице. | K14: XML ошибка на ифт не воспроизвелась, интеграционно не воспроизвелась
A15: 9 | B15: NWR-40 | C15: ПЗ.docx | D15: explanatory_note | E15: ошибка | F15: =D15=E15 -> FALSE | G15: explanatory_note | H15: =D15=G15 -> TRUE | I15: да | J15: XML ошибка не воспроизвелась. Классификация работает корректно | K15: XML ошибка на ифт не воспроизвелась, интеграционно не воспроизвелась
A16: 10 | B16: NWR-42 | C16: Screenshot_20260419-094314_Drive.jpg | D16: tax_declaration | E16: other | F16: =D16=E16 -> FALSE | G16: уведомление о налоговой декларации | H16: =D16=G16 -> FALSE | I16: нет | J16: Не правильно указан тип документа.
A17: 10 | B17: NWR-42 | C17: Screenshot_20260419-094320_Drive.jpg | D17: tax_declaration | E17: other | F17: =D17=E17 -> FALSE | G17: уведомление о налоговой декларации | H17: =D17=G17 -> FALSE | I17: нет | J17: Не правильно указан тип документа.
A18: 10 | B18: NWR-42 | C18: Screenshot_20260419-094159_Drive.jpg | D18: extended_acc_statement_12_months | E18: extended_acc_statement_12_months | F18: =D18=E18 -> TRUE | G18: extended_acc_statement_12_months | H18: =D18=G18 -> TRUE | I18: нет | J18: Всё корректно.
A19: 10 | B19: NWR-42 | C19: Screenshot_20260417-170732_Drive.jpg | D19: explanatory_note | E19: explanatory_note | F19: =D19=E19 -> TRUE | G19: explanatory_note | H19: =D19=G19 -> TRUE | I19: нет | J19: Плохо отсканирован документ. Искривление текста (дуга). Извлечение атрибутов 0 из 2.
A20: 11 | B20: NWR-43 | C20: ИП_Калиничева_Дарья_Антоновна_251008916027-_Декларация_по_упрощенной_системе_налогообложения_за_2025_год.pdf | D20: tax_declaration | E20: ошибка | F20: =D20=E20 -> FALSE | G20: tax_declaration | H20: =D20=G20 -> TRUE | I20: да | J20: Отдельно загруженный документ прошел без ошибок. Атрибутов 2 из 3 извлечено. | K20: исправлено
A21: 11 | B21: NWR-43 | C21: Экспорт_чеков_от_20-04-2026.xlsx | D21: extended_acc_statement_12_months | E21: ошибка | F21: =D21=E21 -> FALSE | G21: экспорт чеков | H21: =D21=G21 -> FALSE | I21: да | J21: Падает из-за этого документа. Xlsx. Отключена регулярка баговая в Выписке за 12 месяцев в классификации. | K21: исправлено
A22: 11 | B22: NWR-43 | C22: 2_5416061250402557620.pdf | D22: extended_acc_statement_12_months | E22: ошибка | F22: =D22=E22 -> FALSE | G22: extended_acc_statement_12_months | H22: =D22=G22 -> TRUE | I22: да | J22: Отдельно загруженный документ прошел без ошибок. Выписка.. | K22: исправлено
A23: 11 | B23: NWR-43 | C23: письмо_пояснение.pdf | D23: explanatory_note | E23: ошибка | F23: =D23=E23 -> FALSE | G23: explanatory_note | H23: =D23=G23 -> TRUE | I23: да | J23: Отдельно загруженный документ прошел без ошибок. Атрибутов 2 из 2 извлечено. | K23: исправлено
A24: 12 | B24: NWR-44 | C24: downloadfile.PDF | D24: tax_declaration | E24: other | F24: =D24=E24 -> FALSE | G24: выписка | H24: =D24=G24 -> FALSE | I24: нет | J24: Не правильно указан тип документа.
A25: 12 | B25: NWR-44 | C25: downloadfile.PDF | D25: extended_acc_statement_12_months | E25: other | F25: =D25=E25 -> FALSE | G25: extended_acc_statement_12_months | H25: =D25=G25 -> TRUE | I25: да | J25: Должна классифицироваться, поправить алгоритм
A26: 12 | B26: NWR-44 | C26: downloadfile.PDF | D26: explanatory_note | E26: other | F26: =D26=E26 -> FALSE | G26: выписка | H26: =D26=G26 -> FALSE | I26: нет | J26: Не правильно указан тип документа.
A27: 13 | B27: NWR-45 | C27: 4080281052******0300_044525104_(01.01.2026_-_19.04_(3).pdf | D27: extended_acc_statement_12_months | E27: extended_acc_statement_12_months | F27: =D27=E27 -> TRUE | G27: extended_acc_statement_12_months | H27: =D27=G27 -> TRUE | I27: нет | J27: Всё корректно.
A28: 13 | B28: NWR-45 | C28: Лист_записи_ЕГРИП_от_19.11.2025.pdf | D28: patent | E28: other | F28: =D28=E28 -> FALSE | G28: Лист записи единого государственного реестра ип | H28: =D28=G28 -> FALSE | I28: нет | J28: Не правильно указан тип документа.
A29: 13 | B29: NWR-45 | C29: Без_названия153_20260420172428.jpg | D29: explanatory_note | E29: other | F29: =D29=E29 -> FALSE | G29: пояснительная, мало текста | H29: =D29=G29 -> FALSE | I29: нет | J29: Нет ключевых слов, мало текста
A30: 14 | B30: NWR-46 | C30: Выписка_рсч_ИП_40802810604500004212_044525104_(21.01.2026_-_20.04.2026).pdf | D30: extended_acc_statement_12_months | E30: extended_acc_statement_12_months | F30: =D30=E30 -> TRUE | G30: extended_acc_statement_12_months | H30: =D30=G30 -> TRUE | I30: нет | J30: Всё корректно.
A31: 14 | B31: NWR-46 | C31: Патент_2026.pdf | D31: patent | E31: patent | F31: =D31=E31 -> TRUE | G31: patent | H31: =D31=G31 -> TRUE | I31: да | J31: Поправим обработку будущей даты | K31: исправлено
A32: 14 | B32: NWR-46 | C32: Пояснение_от_21042026(1).pdf | D32: explanatory_note | E32: explanatory_note | F32: =D32=E32 -> TRUE | G32: explanatory_note | H32: =D32=G32 -> TRUE | I32: нет | J32: Всё корректно.
A33: 15 | B33: NWR-47 | C33: VTB_BankStatement_some_accounts_01.01.2026-31.01.2026_71608_additional_filter.pdf | D33: extended_acc_statement_12_months | E33: other | F33: =D33=E33 -> FALSE | G33: extended_acc_statement_12_months | H33: =D33=G33 -> TRUE | I33: да | J33: Должна классифицироваться, поправить алгоритм
A34: 15 | B34: NWR-47 | C34: ПСН_матина_2025_3.pdf | D34: patent | E34: patent | F34: =D34=E34 -> TRUE | G34: patent | H34: =D34=G34 -> TRUE | I34: нет | J34: Всё корректно.
A35: 15 | B35: NWR-47 | C35: 001.jpg | D35: explanatory_note | E35: explanatory_note | F35: =D35=E35 -> TRUE | G35: explanatory_note | H35: =D35=G35 -> TRUE | I35: нет | J35: Всё корректно.
A36: 16 | B36: NWR-48 | C36: IMG_20260421_1131443838454130856824404.jpg | D36: tax_declaration | E36: other | F36: =D36=E36 -> FALSE | G36: уведомление о постановке на учет в налоговом органе | H36: =D36=G36 -> FALSE | I36: нет | J36: Не правильно указан тип документа.
A37: 16 | B37: NWR-48 | C37: IMG_20260421_113223443727870416881062.jpg | D37: extended_acc_statement_12_months | E37: other | F37: =D37=E37 -> FALSE | G37: книга учета дохода и расхода организации | H37: =D37=G37 -> FALSE | I37: нет | J37: Не правильно указан тип документа, плохое качество
A38: 16 | B38: NWR-48 | C38: IMG_20260421_1132411903660259320353903.jpg | D38: extended_acc_statement_12_months | E38: other | F38: =D38=E38 -> FALSE | G38: книга учета дохода и расхода организации | H38: =D38=G38 -> FALSE | I38: нет | J38: Не правильно указан тип документа, плохое качество
A39: 16 | B39: NWR-48 | C39: IMG_20260421_1132488631474415844664341.jpg | D39: extended_acc_statement_12_months | E39: other | F39: =D39=E39 -> FALSE | G39: книга учета дохода и расхода организации | H39: =D39=G39 -> FALSE | I39: нет | J39: Не правильно указан тип документа, плохое качество
A40: 16 | B40: NWR-48 | C40: IMG_20260421_1132561364630175643485507.jpg | D40: extended_acc_statement_12_months | E40: other | F40: =D40=E40 -> FALSE | G40: книга учета дохода и расхода организации | H40: =D40=G40 -> FALSE | I40: нет | J40: Не правильно указан тип документа, плохое качество
...

Sheet Ошибки клиента
A1: Ошибки клиента
A2: ="📊 Всего документов: "&COUNTA(Лист1!H:H)-1 -> 📊 Всего документов: 86
A3: ="✅ Верно: "&COUNTIF(Лист1!H:H,"ИСТИНА")&" ("&TEXT(COUNTIF(Лист1!H:H,"ИСТИНА")/(COUNTA(Лист1!H:H)-1)*100,"0,0")&"%) "&REPT("█",ROUND(COUNTIF(Лист1!H:H,"ИСТИНА")/(COUNTA(Лист1!H:H)-1)*30,0))&REPT("░",30-ROUND(COUNTIF(Лист1!H:H,"ИСТИНА")/(COUNTA(Лист1!H:H)-1)*30,0)) -> ✅ Верно: 40 (46,5%) ██████████████░░░░░░░░░░░░░░░░
A4: ="❌ Ошибся: "&COUNTIF(Лист1!H:H,"ЛОЖЬ")&" ("&TEXT(COUNTIF(Лист1!H:H,"ЛОЖЬ")/(COUNTA(Лист1!H:H)-1)*100,"0,0")&"%) "&REPT("█",ROUND(COUNTIF(Лист1!H:H,"ЛОЖЬ")/(COUNTA(Лист1!H:H)-1)*30,0))&REPT("░",30-ROUND(COUNTIF(Лист1!H:H,"ЛОЖЬ")/(COUNTA(Лист1!H:H)-1)*30,0)) -> ❌ Ошибся: 46 (53,5%) ████████████████░░░░░░░░░░░░░░
A6: Детализация ошибок
A7: расхождение присланный/реальный | B7: ЛОЖЬ
A9: Документ | B9: Количество ошибок клиента
A10: explanatory_note | B10: 12
A11: пояснительная рукописная | B11: 3
A12: пояснительная, мало текста | B12: 3
A13: трудовой договор | B13: 2
A14: договор аренды | B14: 1
A15: выписка из лицевого счета | B15: 1
A16: выписка | B16: 1
A17: уведомление об осуществлении труд деятельности иностранным гражданином | B17: 1
A18: extended_acc_statement_12_months | B18: 10
A19: книга учета дохода и расхода организации | B19: 6
A20: экспорт чеков | B20: 1
A21: патент | B21: 1
... A48: Общий итог | B48: 46

Sheet Ошибки 1481
A1: Ошибки системы 1481
A2: ="📊 Всего документов: "&COUNTA(Лист1!I:I)-1 -> 📊 Всего документов: 86
A3: ="✅ 1481 отработала верно: "&COUNTIF(Лист1!I:I,"нет")&" ("&TEXT(COUNTIF(Лист1!I:I,"нет")/(COUNTA(Лист1!I:I)-1)*100,"0,0")&"%) "&REPT("█",ROUND(COUNTIF(Лист1!I:I,"нет")/(COUNTA(Лист1!I:I)-1)*30,0))&REPT("░",30-ROUND(COUNTIF(Лист1!I:I,"нет")/(COUNTA(Лист1!I:I)-1)*30,0)) -> ✅ 1481 отработала верно: 57 (66,3%) ████████████████████░░░░░░░░░░
A4: ="❌ 1481 ошиблась: "&COUNTIF(Лист1!I:I,"да")&" ("&TEXT(COUNTIF(Лист1!I:I,"да")/(COUNTA(Лист1!I:I)-1)*100,"0,0")&"%) "&REPT("█",ROUND(COUNTIF(Лист1!I:I,"да")/(COUNTA(Лист1!I:I)-1)*30,0))&REPT("░",30-ROUND(COUNTIF(Лист1!I:I,"да")/(COUNTA(Лист1!I:I)-1)*30,0)) -> ❌ 1481 ошиблась: 20 (23,3%) ███████░░░░░░░░░░░░░░░░░░░░░░░
A5: =" └─ пакетные ошибки (ошибка в ответе 1481): "&COUNTIF(Лист1!E:E,"ошибка")&" ("&TEXT(COUNTIF(Лист1!E:E,"ошибка")/COUNTIF(Лист1!I:I,"да")*100,"0,0")&"% от "&COUNTIF(Лист1!I:I,"да")&") "&REPT("█",ROUND(COUNTIF(Лист1!E:E,"ошибка")/COUNTIF(Лист1!I:I,"да")*30,0))&REPT("░",30-ROUND(COUNTIF(Лист1!E:E,"ошибка")/COUNTIF(Лист1!I:I,"да")*30,0)) -> └─ пакетные ошибки (ошибка в ответе 1481): 11 (55,0% от 20) █████████████████░░░░░░░░░░░░░
A6: =" └─ единичные ошибки (other/не ошибка): "&COUNTIF(Лист1!I:I,"да")-COUNTIF(Лист1!E:E,"ошибка")&" ("&TEXT((COUNTIF(Лист1!I:I,"да")-COUNTIF(Лист1!E:E,"ошибка"))/COUNTIF(Лист1!I:I,"да")*100,"0,0")&"% от "&COUNTIF(Лист1!I:I,"да")&") "&REPT("█",ROUND((COUNTIF(Лист1!I:I,"да")-COUNTIF(Лист1!E:E,"ошибка"))/COUNTIF(Лист1!I:I,"да")*30,0))&REPT("░",30-ROUND((COUNTIF(Лист1!I:I,"да")-COUNTIF(Лист1!E:E,"ошибка"))/COUNTIF(Лист1!I:I,"да")*30,0)) -> └─ единичные ошибки (other/не ошибка): 9 (45,0% от 20) ██████████████░░░░░░░░░░░░░░░░
A7: ="❓ Требует обсуждения: "&COUNTIF(Лист1!I:I,"вопрос")&" ("&TEXT(COUNTIF(Лист1!I:I,"вопрос")/(COUNTA(Лист1!I:I)-1)*100,"0,0")&"%) "&REPT("█",ROUND(COUNTIF(Лист1!I:I,"вопрос")/(COUNTA(Лист1!I:I)-1)*30,0))&REPT("░",30-ROUND(COUNTIF(Лист1!I:I,"вопрос")/(COUNTA(Лист1!I:I)-1)*30,0)) -> ❓ Требует обсуждения: 9 (10,5%) ███░░░░░░░░░░░░░░░░░░░░░░░░░░░
A9: Детализация ошибок
A10: ошибка 1481 | B10: да
A12: Документ | B12: Количество ошибок 1481
A13: extended_acc_statement_12_months | B13: 8
A14: explanatory_note | B14: 5
A15: patent | B15: 4
A16: explanatory_note_crypt | B16: 2
A17: tax_declaration | B17: 1
A18: Общий итог | B18: 20
